Workbook

Sheet WL & Q
A1: 2026 Kelani Flood
A2: Hourly Water Level & Discharges
B3: N'Street | C3: Hanwella | F3: Glencourse | I3: Kithulgala | L3: Holombuwa | O3: Deraniyagala | R3: Norwood
B4: WL (ft) | C4: WL (m) | D4: Q (m3s-1) | E4: RF (mm) | F4: WL (m) | G4: Q (m3s-1) | H4: RF (mm) | I4: WL (m) | J4: Q (m3s-1) | K4: RF (mm) | L4: WL (m) | M4: Q (m3s-1) | N4: RF (mm) | O4: WL (m) | P4: Q (m3s-1) | Q4: RF (mm) | R4: WL (m) | S4: Q (m3s-1) | T4: RF (mm)
A5: 46232.042 | B5: 1.2 | C5: 0.47 | D5: =IF(C5="","",IF((C5+0.56)>4,13.194*(C5+0.56)^2+13.311*(C5+0.56)-0.8227,27.012*(C5+0.56)^1.6477)) -> 28.360157 | E5: 0 | F5: 8.85 | G5: =IF(F5="","",IF((F5-0.118)>14,9.8381*((F5-0.118)-7.5)^2+42.44*((F5-0.118)-7.5)-16.777,35.535*((F5-0.118)-7.5)^1.5414)) -> 49.014397 | H5: 0 | I5: 1.68 | J5: =IF(I5="","",IF(I5<=2.1,7.5134*(I5)^3.1739,31.402*(I5)^2-35.839*(I5)+15.632)) -> 38.989318 | K5: 0 | L5: 0.3 | M5: =IF(L5="","",IF((L5)>2,8.9271*((L5)^2)+9.2434*(L5)-1.6791,14.51*(((L5)-0.1)^1.846))) -> 0.74365035 | N5: 0 | O5: 0.57 | P5: =IF(O5="","",28.62*(O5)^1.3838) -> 13.147684 | Q5: 2.3 | R5: 0.42 | S5: =IF(R5="","",IF(R5>2.5,19.135*(R5+0.5)^2-29.477*(R5+0.5)+32.54,3.0494*((R5+0.5)^2.8875))) -> 2.3969101 | T5: 1.5
A6: =A5+1/24 -> 46232.083 | B6: 1.4 | C6: 0.47 | D6: =IF(C6="","",IF((C6+0.56)>4,13.194*(C6+0.56)^2+13.311*(C6+0.56)-0.8227,27.012*(C6+0.56)^1.6477)) -> 28.360157 | E6: 0 | F6: 8.91 | G6: =IF(F6="","",IF((F6-0.118)>14,9.8381*((F6-0.118)-7.5)^2+42.44*((F6-0.118)-7.5)-16.777,35.535*((F6-0.118)-7.5)^1.5414)) -> 52.741971 | H6: 1 | I6: 1.66 | J6: =IF(I6="","",IF(I6<=2.1,7.5134*(I6)^3.1739,31.402*(I6)^2-35.839*(I6)+15.632)) -> 37.535099 | K6: 0 | L6: 0.27 | M6: =IF(L6="","",IF((L6)>2,8.9271*((L6)^2)+9.2434*(L6)-1.6791,14.51*(((L6)-0.1)^1.846))) -> 0.55090425 | N6: 2.8 | O6: 0.51 | P6: =IF(O6="","",28.62*(O6)^1.3838) -> 11.272111 | Q6: 0.5 | R6: 0.42 | S6: =IF(R6="","",IF(R6>2.5,19.135*(R6+0.5)^2-29.477*(R6+0.5)+32.54,3.0494*((R6+0.5)^2.8875))) -> 2.3969101 | T6: 0
A7: =A6+1/24 -> 46232.125 | B7: 1.3 | C7: 0.48 | D7: =IF(C7="","",IF((C7+0.56)>4,13.194*(C7+0.56)^2+13.311*(C7+0.56)-0.8227,27.012*(C7+0.56)^1.6477)) -> 28.815262 | E7: 0 | F7: 9.05 | G7: =IF(F7="","",IF((F7-0.118)>14,9.8381*((F7-0.118)-7.5)^2+42.44*((F7-0.118)-7.5)-16.777,35.535*((F7-0.118)-7.5)^1.5414)) -> 61.805466 | H7: 0 | I7: 1.66 | J7: =IF(I7="","",IF(I7<=2.1,7.5134*(I7)^3.1739,31.402*(I7)^2-35.839*(I7)+15.632)) -> 37.535099 | K7: 0 | L7: 0.24 | M7: =IF(L7="","",IF((L7)>2,8.9271*((L7)^2)+9.2434*(L7)-1.6791,14.51*(((L7)-0.1)^1.846))) -> 0.38496369 | N7: 0 | O7: 0.45 | P7: =IF(O7="","",28.62*(O7)^1.3838) -> 9.4794929 | Q7: 0 | R7: 0.41 | S7: =IF(R7="","",IF(R7>2.5,19.135*(R7+0.5)^2-29.477*(R7+0.5)+32.54,3.0494*((R7+0.5)^2.8875))) -> 2.3224502 | T7: 1
A8: =A7+1/24 -> 46232.167 | B8: 1 | C8: 0.49 | D8: =IF(C8="","",IF((C8+0.56)>4,13.194*(C8+0.56)^2+13.311*(C8+0.56)-0.8227,27.012*(C8+0.56)^1.6477)) -> 29.27321 | E8: 0 | F8: 9.13 | G8: =IF(F8="","",IF((F8-0.118)>14,9.8381*((F8-0.118)-7.5)^2+42.44*((F8-0.118)-7.5)-16.777,35.535*((F8-0.118)-7.5)^1.5414)) -> 67.207455 | H8: 0 | I8: 1.59 | J8: =IF(I8="","",IF(I8<=2.1,7.5134*(I8)^3.1739,31.402*(I8)^2-35.839*(I8)+15.632)) -> 32.737902 | K8: 0 | L8: 0.22 | M8: =IF(L8="","",IF((L8)>2,8.9271*((L8)^2)+9.2434*(L8)-1.6791,14.51*(((L8)-0.1)^1.846))) -> 0.28962496 | N8: 0 | O8: 0.43 | P8: =IF(O8="","",28.62*(O8)^1.3838) -> 8.9015017 | Q8: 0 | R8: 0.42 | S8: =IF(R8="","",IF(R8>2.5,19.135*(R8+0.5)^2-29.477*(R8+0.5)+32.54,3.0494*((R8+0.5)^2.8875))) -> 2.3969101 | T8: 0
A9: =A8+1/24 -> 46232.208 | B9: 0.8 | C9: 0.51 | D9: =IF(C9="","",IF((C9+0.56)>4,13.194*(C9+0.56)^2+13.311*(C9+0.56)-0.8227,27.012*(C9+0.56)^1.6477)) -> 30.197597 | E9: 0 | F9: 9.1 | G9: =IF(F9="","",IF((F9-0.118)>14,9.8381*((F9-0.118)-7.5)^2+42.44*((F9-0.118)-7.5)-16.777,35.535*((F9-0.118)-7.5)^1.5414)) -> 65.163101 | H9: 3.3 | I9: 1.59 | J9: =IF(I9="","",IF(I9<=2.1,7.5134*(I9)^3.1739,31.402*(I9)^2-35.839*(I9)+15.632)) -> 32.737902 | K9: 9.8 | L9: 0.22 | M9: =IF(L9="","",IF((L9)>2,8.9271*((L9)^2)+9.2434*(L9)-1.6791,14.51*(((L9)-0.1)^1.846))) -> 0.28962496 | N9: 0 | O9: 0.43 | P9: =IF(O9="","",28.62*(O9)^1.3838) -> 8.9015017 | Q9: 8.2 | R9: 0.44 | S9: =IF(R9="","",IF(R9>2.5,19.135*(R9+0.5)^2-29.477*(R9+0.5)+32.54,3.0494*((R9+0.5)^2.8875))) -> 2.550475 | T9: 0
A10: =A9+1/24 -> 46232.25 | B10: 0.6 | C10: 0.55 | D10: =IF(C10="","",IF((C10+0.56)>4,13.194*(C10+0.56)^2+13.311*(C10+0.56)-0.8227,27.012*(C10+0.56)^1.6477)) -> 32.080078 | E10: 3.1 | F10: 9.08 | G10: =IF(F10="","",IF((F10-0.118)>14,9.8381*((F10-0.118)-7.5)^2+42.44*((F10-0.118)-7.5)-16.777,35.535*((F10-0.118)-7.5)^1.5414)) -> 63.812565 | H10: 0 | I10: 1.61 | J10: =IF(I10="","",IF(I10<=2.1,7.5134*(I10)^3.1739,31.402*(I10)^2-35.839*(I10)+15.632)) -> 34.062864 | K10: 7 | L10: 0.21 | M10: =IF(L10="","",IF((L10)>2,8.9271*((L10)^2)+9.2434*(L10)-1.6791,14.51*(((L10)-0.1)^1.846))) -> 0.2466484 | N10: 0 | O10: 0.45 | P10: =IF(O10="","",28.62*(O10)^1.3838) -> 9.4794929 | Q10: 0.9 | R10: 0.45 | S10: =IF(R10="","",IF(R10>2.5,19.135*(R10+0.5)^2-29.477*(R10+0.5)+32.54,3.0494*((R10+0.5)^2.8875))) -> 2.6296098 | T10: 0
A11: =A10+1/24 -> 46232.292 | B11: 0.6 | C11: 0.64 | D11: =IF(C11="","",IF((C11+0.56)>4,13.194*(C11+0.56)^2+13.311*(C11+0.56)-0.8227,27.012*(C11+0.56)^1.6477)) -> 36.477384 | E11: 1.5 | F11: 9.06 | G11: =IF(F11="","",IF((F11-0.118)>14,9.8381*((F11-0.118)-7.5)^2+42.44*((F11-0.118)-7.5)-16.777,35.535*((F11-0.118)-7.5)^1.5414)) -> 62.471995 | H11: 0.4 | I11: 1.68 | J11: =IF(I11="","",IF(I11<=2.1,7.5134*(I11)^3.1739,31.402*(I11)^2-35.839*(I11)+15.632)) -> 38.989318 | K11: 1.2 | L11: 0.21 | M11: =IF(L11="","",IF((L11)>2,8.9271*((L11)^2)+9.2434*(L11)-1.6791,14.51*(((L11)-0.1)^1.846))) -> 0.2466484 | N11: 1.1 | O11: 0.51 | P11: =IF(O11="","",28.62*(O11)^1.3838) -> 11.272111 | Q11: 0.6 | R11: 0.45 | S11: =IF(R11="","",IF(R11>2.5,19.135*(R11+0.5)^2-29.477*(R11+0.5)+32.54,3.0494*((R11+0.5)^2.8875))) -> 2.6296098 | T11: 1.2
A12: =A11+1/24 -> 46232.333 | B12: 0.5 | C12: 0.66 | D12: =IF(C12="","",IF((C12+0.56)>4,13.194*(C12+0.56)^2+13.311*(C12+0.56)-0.8227,27.012*(C12+0.56)^1.6477)) -> 37.48451 | E12: 0 | F12: 9.04 | G12: =IF(F12="","",IF((F12-0.118)>14,9.8381*((F12-0.118)-7.5)^2+42.44*((F12-0.118)-7.5)-16.777,35.535*((F12-0.118)-7.5)^1.5414)) -> 61.141453 | H12: 0 | I12: 1.55 | J12: =IF(I12="","",IF(I12<=2.1,7.5134*(I12)^3.1739,31.402*(I12)^2-35.839*(I12)+15.632)) -> 30.19467 | K12: 0 | L12: 0.2 | M12: =IF(L12="","",IF((L12)>2,8.9271*((L12)^2)+9.2434*(L12)-1.6791,14.51*(((L12)-0.1)^1.846))) -> 0.20685566 | N12: 0 | O12: 0.54 | P12: =IF(O12="","",28.62*(O12)^1.3838) -> 12.199896 | Q12: 0 | R12: 0.46 | S12: =IF(R12="","",IF(R12>2.5,19.135*(R12+0.5)^2-29.477*(R12+0.5)+32.54,3.0494*((R12+0.5)^2.8875))) -> 2.7103326 | T12: 0
A13: =A12+1/24 -> 46232.375 | B13: 0.5 | C13: 0.68 | D13: =IF(C13="","",IF((C13+0.56)>4,13.194*(C13+0.56)^2+13.311*(C13+0.56)-0.8227,27.012*(C13+0.56)^1.6477)) -> 38.502387 | E13: 0 | F13: 9.03 | G13: =IF(F13="","",IF((F13-0.118)>14,9.8381*((F13-0.118)-7.5)^2+42.44*((F13-0.118)-7.5)-16.777,35.535*((F13-0.118)-7.5)^1.5414)) -> 60.479964 | H13: 0 | I13: 1.55 | J13: =IF(I13="","",IF(I13<=2.1,7.5134*(I13)^3.1739,31.402*(I13)^2-35.839*(I13)+15.632)) -> 30.19467 | K13: 0 | L13: 0.2 | M13: =IF(L13="","",IF((L13)>2,8.9271*((L13)^2)+9.2434*(L13)-1.6791,14.51*(((L13)-0.1)^1.846))) -> 0.20685566 | N13: 0 | O13: 0.63 | P13: =IF(O13="","",28.62*(O13)^1.3838) -> 15.1007 | Q13: 0 | R13: 0.46 | S13: =IF(R13="","",IF(R13>2.5,19.135*(R13+0.5)^2-29.477*(R13+0.5)+32.54,3.0494*((R13+0.5)^2.8875))) -> 2.7103326 | T13: 0
A14: =A13+1/24 -> 46232.417 | B14: 0.7 | C14: 0.69 | D14: =IF(C14="","",IF((C14+0.56)>4,13.194*(C14+0.56)^2+13.311*(C14+0.56)-0.8227,27.012*(C14+0.56)^1.6477)) -> 39.015338 | E14: 0 | F14: 9.01 | G14: =IF(F14="","",IF((F14-0.118)>14,9.8381*((F14-0.118)-7.5)^2+42.44*((F14-0.118)-7.5)-16.777,35.535*((F14-0.118)-7.5)^1.5414)) -> 59.164587 | H14: 1.2 | I14: 1.33 | J14: =IF(I14="","",IF(I14<=2.1,7.5134*(I14)^3.1739,31.402*(I14)^2-35.839*(I14)+15.632)) -> 18.575018 | K14: 0 | L14: 0.2 | M14: =IF(L14="","",IF((L14)>2,8.9271*((L14)^2)+9.2434*(L14)-1.6791,14.51*(((L14)-0.1)^1.846))) -> 0.20685566 | N14: 0 | O14: 0.63 | P14: =IF(O14="","",28.62*(O14)^1.3838) -> 15.1007 | Q14: 0 | R14: 0.47 | S14: =IF(R14="","",IF(R14>2.5,19.135*(R14+0.5)^2-29.477*(R14+0.5)+32.54,3.0494*((R14+0.5)^2.8875))) -> 2.7926582 | T14: 0
A15: =A14+1/24 -> 46232.458 | B15: 1.1 | C15: 0.7 | D15: =IF(C15="","",IF((C15+0.56)>4,13.194*(C15+0.56)^2+13.311*(C15+0.56)-0.8227,27.012*(C15+0.56)^1.6477)) -> 39.530953 | E15: 0 | F15: 9 | G15: =IF(F15="","",IF((F15-0.118)>14,9.8381*((F15-0.118)-7.5)^2+42.44*((F15-0.118)-7.5)-16.777,35.535*((F15-0.118)-7.5)^1.5414)) -> 58.510717 | H15: 0 | I15: 1.43 | J15: =IF(I15="","",IF(I15<=2.1,7.5134*(I15)^3.1739,31.402*(I15)^2-35.839*(I15)+15.632)) -> 23.380703 | K15: 1.8 | L15: 0.2 | M15: =IF(L15="","",IF((L15)>2,8.9271*((L15)^2)+9.2434*(L15)-1.6791,14.51*(((L15)-0.1)^1.846))) -> 0.20685566 | N15: 0 | O15: 0.48 | P15: =IF(O15="","",28.62*(O15)^1.3838) -> 10.365046 | Q15: 0 | R15: 0.48 | S15: =IF(R15="","",IF(R15>2.5,19.135*(R15+0.5)^2-29.477*(R15+0.5)+32.54,3.0494*((R15+0.5)^2.8875))) -> 2.8766014 | T15: 1.6
A16: =A15+1/24 -> 46232.5 | B16: 1.5 | C16: 0.7 | D16: =IF(C16="","",IF((C16+0.56)>4,13.194*(C16+0.56)^2+13.311*(C16+0.56)-0.8227,27.012*(C16+0.56)^1.6477)) -> 39.530953 | E16: 0 | F16: 8.98 | G16: =IF(F16="","",IF((F16-0.118)>14,9.8381*((F16-0.118)-7.5)^2+42.44*((F16-0.118)-7.5)-16.777,35.535*((F16-0.118)-7.5)^1.5414)) -> 57.210654 | H16: 0 | I16: 1.45 | J16: =IF(I16="","",IF(I16<=2.1,7.5134*(I16)^3.1739,31.402*(I16)^2-35.839*(I16)+15.632)) -> 24.434441 | K16: 4 | L16: 0.2 | M16: =IF(L16="","",IF((L16)>2,8.9271*((L16)^2)+9.2434*(L16)-1.6791,14.51*(((L16)-0.1)^1.846))) -> 0.20685566 | N16: 0 | O16: 0.44 | P16: =IF(O16="","",28.62*(O16)^1.3838) -> 9.1892368 | Q16: 0.4 | R16: 0.48 | S16: =IF(R16="","",IF(R16>2.5,19.135*(R16+0.5)^2-29.477*(R16+0.5)+32.54,3.0494*((R16+0.5)^2.8875))) -> 2.8766014 | T16: 0
A17: =A16+1/24 -> 46232.542 | B17: 1.8 | C17: 0.72 | D17: =IF(C17="","",IF((C17+0.56)>4,13.194*(C17+0.56)^2+13.311*(C17+0.56)-0.8227,27.012*(C17+0.56)^1.6477)) -> 40.570149 | E17: 0 | F17: 9.02 | G17: =IF(F17="","",IF((F17-0.118)>14,9.8381*((F17-0.118)-7.5)^2+42.44*((F17-0.118)-7.5)-16.777,35.535*((F17-0.118)-7.5)^1.5414)) -> 59.821005 | H17: 0 | I17: 1.63 | J17: =IF(I17="","",IF(I17<=2.1,7.5134*(I17)^3.1739,31.402*(I17)^2-35.839*(I17)+15.632)) -> 35.424094 | K17: 0 | L17: 0.2 | M17: =IF(L17="","",IF((L17)>2,8.9271*((L17)^2)+9.2434*(L17)-1.6791,14.51*(((L17)-0.1)^1.846))) -> 0.20685566 | N17: 0 | O17: 0.68 | P17: =IF(O17="","",28.62*(O17)^1.3838) -> 16.784 | Q17: 0 | R17: 0.48 | S17: =IF(R17="","",IF(R17>2.5,19.135*(R17+0.5)^2-29.477*(R17+0.5)+32.54,3.0494*((R17+0.5)^2.8875))) -> 2.8766014 | T17: 0
... A132: =A131+1/24 -> 46237.333 | B132: 1.5 | C132: 4.45 | D132: =IF(C132="","",IF((C132+0.56)>4,13.194*(C132+0.56)^2+13.311*(C132+0.56)-0.8227,27.012*(C132+0.56)^1.6477)) -> 397.03613 | E132: 0 | F132: 14.41 | G132: =IF(F132="","",IF((F132-0.118)>14,9.8381*((F132-0.118)-7.5)^2+42.44*((F132-0.118)-7.5)-16.777,35.535*((F132-0.118)-7.5)^1.5414)) -> 725.31947 | H132: 0 | I132: 2.77 | J132: =IF(I132="","",IF(I132<=2.1,7.5134*(I132)^3.1739,31.402*(I132)^2-35.839*(I132)+15.632)) -> 157.30238 | K132: 5.7 | L132: 1 | M132: =IF(L132="","",IF((L132)>2,8.9271*((L132)^2)+9.2434*(L132)-1.6791,14.51*(((L132)-0.1)^1.846))) -> 11.945356 | N132: 0 | O132: 2.03 | P132: =IF(O132="","",28.62*(O132)^1.3838) -> 76.239958 | Q132: 1.6 | R132: 2.02 | S132: =IF(R132="","",IF(R132>2.5,19.135*(R132+0.5)^2-29.477*(R132+0.5)+32.54,3.0494*((R132+0.5)^2.8875))) -> 43.980327 | T132: 4.6
A133: =A132+1/24 -> 46237.375 | B133: 1.2 | C133: 4.77 | D133: =IF(C133="","",IF((C133+0.56)>4,13.194*(C133+0.56)^2+13.311*(C133+0.56)-0.8227,27.012*(C133+0.56)^1.6477)) -> 444.95196 | E133: 0 | F133: 14.35 | G133: =IF(F133="","",IF((F133-0.118)>14,9.8381*((F133-0.118)-7.5)^2+42.44*((F133-0.118)-7.5)-16.777,35.535*((F133-0.118)-7.5)^1.5414)) -> 714.79004 | H133: 0 | I133: 2.71 | J133: =IF(I133="","",IF(I133<=2.1,7.5134*(I133)^3.1739,31.402*(I133)^2-35.839*(I133)+15.632)) -> 149.12774 | K133: 5 | L133: 1 | M133: =IF(L133="","",IF((L133)>2,8.9271*((L133)^2)+9.2434*(L133)-1.6791,14.51*(((L133)-0.1)^1.846))) -> 11.945356 | N133: 1.4 | O133: 1.83 | P133: =IF(O133="","",28.62*(O133)^1.3838) -> 66.046445 | Q133: 1.6 | R133: 2.19 | S133: =IF(R133="","",IF(R133>2.5,19.135*(R133+0.5)^2-29.477*(R133+0.5)+32.54,3.0494*((R133+0.5)^2.8875))) -> 53.103617 | T133: =12.6+8.8 -> 21.4
A134: =A133+1/24 -> 46237.417 | B134: 1.1 | C134: 4.97 | D134: =IF(C134="","",IF((C134+0.56)>4,13.194*(C134+0.56)^2+13.311*(C134+0.56)-0.8227,27.012*(C134+0.56)^1.6477)) -> 476.27152 | E134: 0 | F134: 14.21 | G134: =IF(F134="","",IF((F134-0.118)>14,9.8381*((F134-0.118)-7.5)^2+42.44*((F134-0.118)-7.5)-16.777,35.535*((F134-0.118)-7.5)^1.5414)) -> 690.49684 | H134: 0 | I134: 2.99 | J134: =IF(I134="","",IF(I134<=2.1,7.5134*(I134)^3.1739,31.402*(I134)^2-35.839*(I134)+15.632)) -> 189.21041 | K134: 16.4 | L134: 0.99 | M134: =IF(L134="","",IF((L134)>2,8.9271*((L134)^2)+9.2434*(L134)-1.6791,14.51*(((L134)-0.1)^1.846))) -> 11.701495 | N134: 1.1 | O134: 1.95 | P134: =IF(O134="","",28.62*(O134)^1.3838) -> 72.11399 | Q134: 0 | R134: 3.06 | S134: =IF(R134="","",IF(R134>2.5,19.135*(R134+0.5)^2-29.477*(R134+0.5)+32.54,3.0494*((R134+0.5)^2.8875))) -> 170.11122 | T134: 34.8
A135: =A134+1/24 -> 46237.458 | B135: 1.4 | C135: 5.11 | D135: =IF(C135="","",IF((C135+0.56)>4,13.194*(C135+0.56)^2+13.311*(C135+0.56)-0.8227,27.012*(C135+0.56)^1.6477)) -> 498.82326 | E135: 0 | F135: 14.05 | G135: =IF(F135="","",IF((F135-0.118)>14,9.8381*((F135-0.118)-7.5)^2+42.44*((F135-0.118)-7.5)-16.777,35.535*((F135-0.118)-7.5)^1.5414)) -> 626.09596 | H135: 2.1 | I135: 5.9 | J135: =IF(I135="","",IF(I135<=2.1,7.5134*(I135)^3.1739,31.402*(I135)^2-35.839*(I135)+15.632)) -> 897.28552 | K135: 65.8 | L135: 0.85 | M135: =IF(L135="","",IF((L135)>2,8.9271*((L135)^2)+9.2434*(L135)-1.6791,14.51*(((L135)-0.1)^1.846))) -> 8.5316004 | N135: 0 | O135: 2.68 | P135: =IF(O135="","",28.62*(O135)^1.3838) -> 111.97538 | Q135: 12.3 | R135: 3.3 | S135: =IF(R135="","",IF(R135>2.5,19.135*(R135+0.5)^2-29.477*(R135+0.5)+32.54,3.0494*((R135+0.5)^2.8875))) -> 196.8368 | T135: 4.8
A136: =A135+1/24 -> 46237.5 | B136: 1.55 | C136: 5.18 | D136: =IF(C136="","",IF((C136+0.56)>4,13.194*(C136+0.56)^2+13.311*(C136+0.56)-0.8227,27.012*(C136+0.56)^1.6477)) -> 510.29307 | E136: 0 | F136: 13.81 | G136: =IF(F136="","",IF((F136-0.118)>14,9.8381*((F136-0.118)-7.5)^2+42.44*((F136-0.118)-7.5)-16.777,35.535*((F136-0.118)-7.5)^1.5414)) -> 590.45192 | H136: 1.5 | I136: 7.5 | J136: =IF(I136="","",IF(I136<=2.1,7.5134*(I136)^3.1739,31.402*(I136)^2-35.839*(I136)+15.632)) -> 1513.202 | K136: 22.9 | L136: 0.94 | M136: =IF(L136="","",IF((L136)>2,8.9271*((L136)^2)+9.2434*(L136)-1.6791,14.51*(((L136)-0.1)^1.846))) -> 10.516881 | N136: 2.2 | O136: 3.3 | P136: =IF(O136="","",28.62*(O136)^1.3838) -> 149.3445 | Q136: 8.6 | R136: 3.19 | S136: =IF(R136="","",IF(R136>2.5,19.135*(R136+0.5)^2-29.477*(R136+0.5)+32.54,3.0494*((R136+0.5)^2.8875))) -> 184.31394 | T136: 28.6
A137: =A136+1/24 -> 46237.542 | B137: 1.9 | C137: 5.2 | D137: =IF(C137="","",IF((C137+0.56)>4,13.194*(C137+0.56)^2+13.311*(C137+0.56)-0.8227,27.012*(C137+0.56)^1.6477)) -> 513.59391 | E137: 2 | F137: 13.68 | G137: =IF(F137="","",IF((F137-0.118)>14,9.8381*((F137-0.118)-7.5)^2+42.44*((F137-0.118)-7.5)-16.777,35.535*((F137-0.118)-7.5)^1.5414)) -> 571.453 | H137: 2 | I137: 7.18 | J137: =IF(I137="","",IF(I137<=2.1,7.5134*(I137)^3.1739,31.402*(I137)^2-35.839*(I137)+15.632)) -> 1377.1564 | K137: 8.7 | L137: 1.48 | M137: =IF(L137="","",IF((L137)>2,8.9271*((L137)^2)+9.2434*(L137)-1.6791,14.51*(((L137)-0.1)^1.846))) -> 26.295668 | N137: 2.8 | O137: 5.25 | P137: =IF(O137="","",28.62*(O137)^1.3838) -> 283.93967 | Q137: 6 | R137: 3.42 | S137: =IF(R137="","",IF(R137>2.5,19.135*(R137+0.5)^2-29.477*(R137+0.5)+32.54,3.0494*((R137+0.5)^2.8875))) -> 211.02622 | T137: 22.8
A138: =A137+1/24 -> 46237.583 | B138: 2.2 | C138: 5.18 | D138: =IF(C138="","",IF((C138+0.56)>4,13.194*(C138+0.56)^2+13.311*(C138+0.56)-0.8227,27.012*(C138+0.56)^1.6477)) -> 510.29307 | E138: 0.8 | F138: 14 | G138: =IF(F138="","",IF((F138-0.118)>14,9.8381*((F138-0.118)-7.5)^2+42.44*((F138-0.118)-7.5)-16.777,35.535*((F138-0.118)-7.5)^1.5414)) -> 618.60971 | H138: 1.6 | I138: 6.71 | J138: =IF(I138="","",IF(I138<=2.1,7.5134*(I138)^3.1739,31.402*(I138)^2-35.839*(I138)+15.632)) -> 1188.9991 | K138: 4.9 | L138: 3.02 | M138: =IF(L138="","",IF((L138)>2,8.9271*((L138)^2)+9.2434*(L138)-1.6791,14.51*(((L138)-0.1)^1.846))) -> 107.65469 | N138: 2.5 | O138: 6.24 | P138: =IF(O138="","",28.62*(O138)^1.3838) -> 360.61689 | Q138: 5.2 | R138: 3.38 | S138: =IF(R138="","",IF(R138>2.5,19.135*(R138+0.5)^2-29.477*(R138+0.5)+32.54,3.0494*((R138+0.5)^2.8875))) -> 206.23518 | T138: 10.2
A139: =A138+1/24 -> 46237.625 | B139: 2.55 | C139: 5.18 | D139: =IF(C139="","",IF((C139+0.56)>4,13.194*(C139+0.56)^2+13.311*(C139+0.56)-0.8227,27.012*(C139+0.56)^1.6477)) -> 510.29307 | E139: 0.5 | F139: 14.6 | G139: =IF(F139="","",IF((F139-0.118)>14,9.8381*((F139-0.118)-7.5)^2+42.44*((F139-0.118)-7.5)-16.777,35.535*((F139-0.118)-7.5)^1.5414)) -> 759.12997 | H139: 3 | I139: 5.33 | J139: =IF(I139="","",IF(I139<=2.1,7.5134*(I139)^3.1739,31.402*(I139)^2-35.839*(I139)+15.632)) -> 716.70641 | K139: 1.5 | L139: 3.75 | M139: =IF(L139="","",IF((L139)>2,8.9271*((L139)^2)+9.2434*(L139)-1.6791,14.51*(((L139)-0.1)^1.846))) -> 158.52099 | N139: 0.6 | O139: 5.85 | P139: =IF(O139="","",28.62*(O139)^1.3838) -> 329.80704 | Q139: 1.7 | R139: 3.11 | S139: =IF(R139="","",IF(R139>2.5,19.135*(R139+0.5)^2-29.477*(R139+0.5)+32.54,3.0494*((R139+0.5)^2.8875))) -> 175.49726 | T139: 8.2
A140: =A139+1/24 -> 46237.667 | B140: 2.7 | C140: 5.32 | D140: =IF(C140="","",IF((C140+0.56)>4,13.194*(C140+0.56)^2+13.311*(C140+0.56)-0.8227,27.012*(C140+0.56)^1.6477)) -> 533.62061 | E140: 0.3 | F140: 15.17 | G140: =IF(F140="","",IF((F140-0.118)>14,9.8381*((F140-0.118)-7.5)^2+42.44*((F140-0.118)-7.5)-16.777,35.535*((F140-0.118)-7.5)^1.5414)) -> 864.82333 | H140: 1.2 | I140: 4.13 | J140: =IF(I140="","",IF(I140<=2.1,7.5134*(I140)^3.1739,31.402*(I140)^2-35.839*(I140)+15.632)) -> 403.2377 | K140: 0.5 | L140: 3.9 | M140: =IF(L140="","",IF((L140)>2,8.9271*((L140)^2)+9.2434*(L140)-1.6791,14.51*(((L140)-0.1)^1.846))) -> 170.15135 | N140: 1.2 | O140: 5.11 | P140: =IF(O140="","",28.62*(O140)^1.3838) -> 273.51583 | Q140: 0.3 | R140: 2.78 | S140: =IF(R140="","",IF(R140>2.5,19.135*(R140+0.5)^2-29.477*(R140+0.5)+32.54,3.0494*((R140+0.5)^2.8875))) -> 141.71742 | T140: 2.4
A141: =A140+1/24 -> 46237.708 | B141: 2.8 | C141: 5.55 | D141: =IF(C141="","",IF((C141+0.56)>4,13.194*(C141+0.56)^2+13.311*(C141+0.56)-0.8227,27.012*(C141+0.56)^1.6477)) -> 573.06724 | E141: 0.2 | F141: 15.65 | G141: =IF(F141="","",IF((F141-0.118)>14,9.8381*((F141-0.118)-7.5)^2+42.44*((F141-0.118)-7.5)-16.777,35.535*((F141-0.118)-7.5)^1.5414)) -> 958.78666 | H141: 1.5 | I141: 3.5 | J141: =IF(I141="","",IF(I141<=2.1,7.5134*(I141)^3.1739,31.402*(I141)^2-35.839*(I141)+15.632)) -> 274.87 | K141: 0 | L141: 3.68 | M141: =IF(L141="","",IF((L141)>2,8.9271*((L141)^2)+9.2434*(L141)-1.6791,14.51*(((L141)-0.1)^1.846))) -> 153.23097 | N141: 0.6 | O141: 4.31 | P141: =IF(O141="","",28.62*(O141)^1.3838) -> 216.10224 | Q141: 0 | R141: 2.55 | S141: =IF(R141="","",IF(R141>2.5,19.135*(R141+0.5)^2-29.477*(R141+0.5)+32.54,3.0494*((R141+0.5)^2.8875))) -> 120.63849 | T141: 0.5
A142: =A141+1/24 -> 46237.75 | B142: 2.75 | C142: 5.8 | D142: =IF(C142="","",IF((C142+0.56)>4,13.194*(C142+0.56)^2+13.311*(C142+0.56)-0.8227,27.012*(C142+0.56)^1.6477)) -> 617.52728 | E142: 0.3 | F142: 15.96 | G142: =IF(F142="","",IF((F142-0.118)>14,9.8381*((F142-0.118)-7.5)^2+42.44*((F142-0.118)-7.5)-16.777,35.535*((F142-0.118)-7.5)^1.5414)) -> 1021.8807 | H142: 0.6 | I142: 3.3 | J142: =IF(I142="","",IF(I142<=2.1,7.5134*(I142)^3.1739,31.402*(I142)^2-35.839*(I142)+15.632)) -> 239.33108 | K142: 0 | L142: 3.11 | M142: =IF(L142="","",IF((L142)>2,8.9271*((L142)^2)+9.2434*(L142)-1.6791,14.51*(((L142)-0.1)^1.846))) -> 113.41168 | N142: 0 | O142: 3.41 | P142: =IF(O142="","",28.62*(O142)^1.3838) -> 156.27703 | Q142: 0.6 | R142: 2.28 | S142: =IF(R142="","",IF(R142>2.5,19.135*(R142+0.5)^2-29.477*(R142+0.5)+32.54,3.0494*((R142+0.5)^2.8875))) -> 58.397431 | T142: 0
A143: =A142+1/24 -> 46237.792 | B143: 2.7 | C143: 6.09 | D143: =IF(C143="","",IF((C143+0.56)>4,13.194*(C143+0.56)^2+13.311*(C143+0.56)-0.8227,27.012*(C143+0.56)^1.6477)) -> 671.16711 | E143: 0 | F143: 16.19 | G143: =IF(F143="","",IF((F143-0.118)>14,9.8381*((F143-0.118)-7.5)^2+42.44*((F143-0.118)-7.5)-16.777,35.535*((F143-0.118)-7.5)^1.5414)) -> 1069.9142 | H143: 0 | I143: 3.06 | J143: =IF(I143="","",IF(I143<=2.1,7.5134*(I143)^3.1739,31.402*(I143)^2-35.839*(I143)+15.632)) -> 200.00043 | K143: 0 | L143: 2.7 | M143: =IF(L143="","",IF((L143)>2,8.9271*((L143)^2)+9.2434*(L143)-1.6791,14.51*(((L143)-0.1)^1.846))) -> 88.356639 | N143: 0 | O143: 2.82 | P143: =IF(O143="","",28.62*(O143)^1.3838) -> 120.15016 | Q143: 0 | R143: 2.23 | S143: =IF(R143="","",IF(R143>2.5,19.135*(R143+0.5)^2-29.477*(R143+0.5)+32.54,3.0494*((R143+0.5)^2.8875))) -> 55.415855 | T143: 4.8
A144: =A143+1/24 -> 46237.833 | B144: 2.4 | C144: 6.35 | D144: =IF(C144="","",IF((C144+0.56)>4,13.194*(C144+0.56)^2+13.311*(C144+0.56)-0.8227,27.012*(C144+0.56)^1.6477)) -> 721.14474 | E144: 0 | F144: 16.33 | G144: =IF(F144="","",IF((F144-0.118)>14,9.8381*((F144-0.118)-7.5)^2+42.44*((F144-0.118)-7.5)-16.777,35.535*((F144-0.118)-7.5)^1.5414)) -> 1099.6617 | H144: 0 | I144: 3.15 | J144: =IF(I144="","",IF(I144<=2.1,7.5134*(I144)^3.1739,31.402*(I144)^2-35.839*(I144)+15.632)) -> 214.32549 | K144: 0 | L144: 2.38 | M144: =IF(L144="","",IF((L144)>2,8.9271*((L144)^2)+9.2434*(L144)-1.6791,14.51*(((L144)-0.1)^1.846))) -> 70.886857 | N144: 0 | O144: 2.63 | P144: =IF(O144="","",28.62*(O144)^1.3838) -> 109.09489 | Q144: 0 | R144: 2.09 | S144: =IF(R144="","",IF(R144>2.5,19.135*(R144+0.5)^2-29.477*(R144+0.5)+32.54,3.0494*((R144+0.5)^2.8875))) -> 47.601152 | T144: 0
A145: =A144+1/24 -> 46237.875 | B145: 2.3 | C145: 6.57 | D145: =IF(C145="","",IF((C145+0.56)>4,13.194*(C145+0.56)^2+13.311*(C145+0.56)-0.8227,27.012*(C145+0.56)^1.6477)) -> 764.82679 | E145: 0 | F145: 16.43 | G145: =IF(F145="","",IF((F145-0.118)>14,9.8381*((F145-0.118)-7.5)^2+42.44*((F145-0.118)-7.5)-16.777,35.535*((F145-0.118)-7.5)^1.5414)) -> 1121.146 | H145: 0 | I145: 2.91 | J145: =IF(I145="","",IF(I145<=2.1,7.5134*(I145)^3.1739,31.402*(I145)^2-35.839*(I145)+15.632)) -> 177.25579 | K145: 0 | L145: 2 | M145: =IF(L145="","",IF((L145)>2,8.9271*((L145)^2)+9.2434*(L145)-1.6791,14.51*(((L145)-0.1)^1.846))) -> 47.45113 | N145: 0 | O145: 2.18 | P145: =IF(O145="","",28.62*(O145)^1.3838) -> 84.144498 | Q145: 0 | R145: 1.82 | S145: =IF(R145="","",IF(R145>2.5,19.135*(R145+0.5)^2-29.477*(R145+0.5)+32.54,3.0494*((R145+0.5)^2.8875))) -> 34.63865 | T145: 0.3
... A160: =A159+1/24 -> 46238.5 | B160: 3.3 | C160: 6.28 | D160: =IF(C160="","",IF((C160+0.56)>4,13.194*(C160+0.56)^2+13.311*(C160+0.56)-0.8227,27.012*(C160+0.56)^1.6477)) -> 707.51375 | E160: 0 | F160: 13.6 | G160: =IF(F160="","",IF((F160-0.118)>14,9.8381*((F160-0.118)-7.5)^2+42.44*((F160-0.118)-7.5)-16.777,35.535*((F160-0.118)-7.5)^1.5414)) -> 559.87023 | H160: 0 | I160: 2.92 | J160: =IF(I160="","",IF(I160<=2.1,7.5134*(I160)^3.1739,31.402*(I160)^2-35.839*(I160)+15.632)) -> 178.72813 | K160: 5 | L160: 1.02 | M160: =IF(L160="","",IF((L160)>2,8.9271*((L160)^2)+9.2434*(L160)-1.6791,14.51*(((L160)-0.1)^1.846))) -> 12.439982 | N160: 0.6 | O160: 1.79 | P160: =IF(O160="","",28.62*(O160)^1.3838) -> 64.057156 | Q160: 11 | R160: 1.36 | S160: =IF(R160="","",IF(R160>2.5,19.135*(R160+0.5)^2-29.477*(R160+0.5)+32.54,3.0494*((R160+0.5)^2.8875))) -> 18.299239 | T160: 0
A161: =A160+1/24 -> 46238.542 | D161: =IF(C161="","",IF((C161+0.56)>4,13.194*(C161+0.56)^2+13.311*(C161+0.56)-0.8227,27.012*(C161+0.56)^1.6477)) | G161: =IF(F161="","",IF((F161-0.118)>14,9.8381*((F161-0.118)-7.5)^2+42.44*((F161-0.118)-7.5)-16.777,35.535*((F161-0.118)-7.5)^1.5414)) | J161: =IF(I161="","",IF(I161<=2.1,7.5134*(I161)^3.1739,31.402*(I161)^2-35.839*(I161)+15.632)) | M161: =IF(L161="","",IF((L161)>2,8.9271*((L161)^2)+9.2434*(L161)-1.6791,14.51*(((L161)-0.1)^1.846))) | P161: =IF(O161="","",28.62*(O161)^1.3838) | S161: =IF(R161="","",IF(R161>2.5,19.135*(R161+0.5)^2-29.477*(R161+0.5)+32.54,3.0494*((R161+0.5)^2.8875)))
A162: =A161+1/24 -> 46238.583 | D162: =IF(C162="","",IF((C162+0.56)>4,13.194*(C162+0.56)^2+13.311*(C162+0.56)-0.8227,27.012*(C162+0.56)^1.6477)) | G162: =IF(F162="","",IF((F162-0.118)>14,9.8381*((F162-0.118)-7.5)^2+42.44*((F162-0.118)-7.5)-16.777,35.535*((F162-0.118)-7.5)^1.5414)) | J162: =IF(I162="","",IF(I162<=2.1,7.5134*(I162)^3.1739,31.402*(I162)^2-35.839*(I162)+15.632)) | M162: =IF(L162="","",IF((L162)>2,8.9271*((L162)^2)+9.2434*(L162)-1.6791,14.51*(((L162)-0.1)^1.846))) | P162: =IF(O162="","",28.62*(O162)^1.3838) | S162: =IF(R162="","",IF(R162>2.5,19.135*(R162+0.5)^2-29.477*(R162+0.5)+32.54,3.0494*((R162+0.5)^2.8875)))
A163: =A162+1/24 -> 46238.625 | D163: =IF(C163="","",IF((C163+0.56)>4,13.194*(C163+0.56)^2+13.311*(C163+0.56)-0.8227,27.012*(C163+0.56)^1.6477)) | G163: =IF(F163="","",IF((F163-0.118)>14,9.8381*((F163-0.118)-7.5)^2+42.44*((F163-0.118)-7.5)-16.777,35.535*((F163-0.118)-7.5)^1.5414)) | J163: =IF(I163="","",IF(I163<=2.1,7.5134*(I163)^3.1739,31.402*(I163)^2-35.839*(I163)+15.632)) | M163: =IF(L163="","",IF((L163)>2,8.9271*((L163)^2)+9.2434*(L163)-1.6791,14.51*(((L163)-0.1)^1.846))) | P163: =IF(O163="","",28.62*(O163)^1.3838) | S163: =IF(R163="","",IF(R163>2.5,19.135*(R163+0.5)^2-29.477*(R163+0.5)+32.54,3.0494*((R163+0.5)^2.8875)))
A164: =A163+1/24 -> 46238.667 | D164: =IF(C164="","",IF((C164+0.56)>4,13.194*(C164+0.56)^2+13.311*(C164+0.56)-0.8227,27.012*(C164+0.56)^1.6477)) | G164: =IF(F164="","",IF((F164-0.118)>14,9.8381*((F164-0.118)-7.5)^2+42.44*((F164-0.118)-7.5)-16.777,35.535*((F164-0.118)-7.5)^1.5414)) | J164: =IF(I164="","",IF(I164<=2.1,7.5134*(I164)^3.1739,31.402*(I164)^2-35.839*(I164)+15.632)) | M164: =IF(L164="","",IF((L164)>2,8.9271*((L164)^2)+9.2434*(L164)-1.6791,14.51*(((L164)-0.1)^1.846))) | P164: =IF(O164="","",28.62*(O164)^1.3838) | S164: =IF(R164="","",IF(R164>2.5,19.135*(R164+0.5)^2-29.477*(R164+0.5)+32.54,3.0494*((R164+0.5)^2.8875)))
A165: =A164+1/24 -> 46238.708 | D165: =IF(C165="","",IF((C165+0.56)>4,13.194*(C165+0.56)^2+13.311*(C165+0.56)-0.8227,27.012*(C165+0.56)^1.6477)) | G165: =IF(F165="","",IF((F165-0.118)>14,9.8381*((F165-0.118)-7.5)^2+42.44*((F165-0.118)-7.5)-16.777,35.535*((F165-0.118)-7.5)^1.5414)) | J165: =IF(I165="","",IF(I165<=2.1,7.5134*(I165)^3.1739,31.402*(I165)^2-35.839*(I165)+15.632)) | M165: =IF(L165="","",IF((L165)>2,8.9271*((L165)^2)+9.2434*(L165)-1.6791,14.51*(((L165)-0.1)^1.846))) | P165: =IF(O165="","",28.62*(O165)^1.3838) | S165: =IF(R165="","",IF(R165>2.5,19.135*(R165+0.5)^2-29.477*(R165+0.5)+32.54,3.0494*((R165+0.5)^2.8875)))
A166: =A165+1/24 -> 46238.75 | D166: =IF(C166="","",IF((C166+0.56)>4,13.194*(C166+0.56)^2+13.311*(C166+0.56)-0.8227,27.012*(C166+0.56)^1.6477)) | G166: =IF(F166="","",IF((F166-0.118)>14,9.8381*((F166-0.118)-7.5)^2+42.44*((F166-0.118)-7.5)-16.777,35.535*((F166-0.118)-7.5)^1.5414)) | J166: =IF(I166="","",IF(I166<=2.1,7.5134*(I166)^3.1739,31.402*(I166)^2-35.839*(I166)+15.632)) | M166: =IF(L166="","",IF((L166)>2,8.9271*((L166)^2)+9.2434*(L166)-1.6791,14.51*(((L166)-0.1)^1.846))) | P166: =IF(O166="","",28.62*(O166)^1.3838) | S166: =IF(R166="","",IF(R166>2.5,19.135*(R166+0.5)^2-29.477*(R166+0.5)+32.54,3.0494*((R166+0.5)^2.8875)))
A167: =A166+1/24 -> 46238.792 | D167: =IF(C167="","",IF((C167+0.56)>4,13.194*(C167+0.56)^2+13.311*(C167+0.56)-0.8227,27.012*(C167+0.56)^1.6477)) | G167: =IF(F167="","",IF((F167-0.118)>14,9.8381*((F167-0.118)-7.5)^2+42.44*((F167-0.118)-7.5)-16.777,35.535*((F167-0.118)-7.5)^1.5414)) | J167: =IF(I167="","",IF(I167<=2.1,7.5134*(I167)^3.1739,31.402*(I167)^2-35.839*(I167)+15.632)) | M167: =IF(L167="","",IF((L167)>2,8.9271*((L167)^2)+9.2434*(L167)-1.6791,14.51*(((L167)-0.1)^1.846))) | P167: =IF(O167="","",28.62*(O167)^1.3838) | S167: =IF(R167="","",IF(R167>2.5,19.135*(R167+0.5)^2-29.477*(R167+0.5)+32.54,3.0494*((R167+0.5)^2.8875)))
A168: =A167+1/24 -> 46238.833 | D168: =IF(C168="","",IF((C168+0.56)>4,13.194*(C168+0.56)^2+13.311*(C168+0.56)-0.8227,27.012*(C168+0.56)^1.6477)) | G168: =IF(F168="","",IF((F168-0.118)>14,9.8381*((F168-0.118)-7.5)^2+42.44*((F168-0.118)-7.5)-16.777,35.535*((F168-0.118)-7.5)^1.5414)) | J168: =IF(I168="","",IF(I168<=2.1,7.5134*(I168)^3.1739,31.402*(I168)^2-35.839*(I168)+15.632)) | M168: =IF(L168="","",IF((L168)>2,8.9271*((L168)^2)+9.2434*(L168)-1.6791,14.51*(((L168)-0.1)^1.846))) | P168: =IF(O168="","",28.62*(O168)^1.3838) | S168: =IF(R168="","",IF(R168>2.5,19.135*(R168+0.5)^2-29.477*(R168+0.5)+32.54,3.0494*((R168+0.5)^2.8875)))
...

Sheet Daily RF
A1: ='WL & Q'!A1 -> 2026 Kelani Flood
A2: Daily Rainfall in mm
A4: Station Name | B4: =DATE(YEAR('WL & Q'!A5),MONTH('WL & Q'!A5),DAY('WL & Q'!A5)) -> 46232 | C4: =B4+1 -> 46233 | D4: =C4+1 -> 46234 | E4: =D4+1 -> 46235 | F4: =E4+1 -> 46236 | G4: =F4+1 -> 46237 | H4: =G4+1 -> 46238 | I4: =H4+1 -> 46239 | J4: =I4+1 -> 46240 | ... N4: =M4+1 -> 46244
A5: Hanwella | B5: 0 | C5: 2 | D5: 13.7 | E5: 1 | F5: 2.7 | G5: 4.4
A6: Glencourse | B6: 1.2 | C6: 13.5 | D6: 63.7 | E6: 1.7 | F6: 11.4 | G6: 18.6
A7: Kithulgala | B7: 5.8 | C7: 8.8 | D7: 151.6 | E7: 12.1 | F7: 144.1 | G7: 138
A8: Holombuwa | B8: 0 | C8: 4.5 | D8: 66.9 | E8: 0 | F8: 8.8 | G8: 14.1
A9: Deraniyagala | B9: 0.4 | C9: 11.7 | D9: 104.6 | E9: 3.9 | F9: 40.7 | G9: 57.4
A10: Norwood | B10: 1.6 | C10: 1.5 | D10: 49.9 | E10: 11.2 | F10: 118.6 | G10: 153.3
A11: Castlereigh(CEB) | B11: 8 | C11: 12 | D11: 71 | E11: 26 | F11: 159 | G11: 164
A12: Norton(CEB) | B12: 7.2 | C12: 21 | D12: 160.4 | E12: 28.7 | F12: 186 | G12: 258.6
A13: Maussakelle(CEB) | B13: 3.5 | C13: 7 | D13: 84 | E13: 25 | F13: 39 | G13: 125
A14: Canyon(CEB) | B14: 5.2 | C14: 12 | D14: 118.9 | E14: 36.4 | F14: 191 | G14: 234.6
A15: Laxapana(CEB) | B15: 6 | C15: 13.9 | D15: 184.3 | E15: 17.5 | F15: 187 | G15: 208.4
A16: Colombo (Irrigation) | B16: 0 | C16: 0 | D16: 5.2 | E16: 2.3 | F16: 0.5 | G16: 0.8

Sheet Hanwella
A1: ='WL & Q'!A1 -> 2026 Kelani Flood
A2: Hanwella | I2: Range | J2: No 01 | K2: No 02 | L2: No 03 | M2: No 04
I3: 0 | J3: 46235.312 | K3: 46237.479 | L3: 46237.562 | M3: 46237.646
B4: WL (m) | C4: Q (m3s-1) | D4: RF | E4: Alert | F4: Minor | G4: Major | I4: 12 | J4: =J3 -> 46235.312 | K4: =K3 -> 46237.479 | L4: =L3 -> 46237.562 | M4: =M3 -> 46237.646
A5: ='WL & Q'!A5 -> 46232.042 | B5: =IF('WL & Q'!C5="","",'WL & Q'!C5) -> 0.47 | C5: =IF(B5="","",IF((B5+0.56)>4,13.194*(B5+0.56)^2+13.311*(B5+0.56)-0.8227,27.012*(B5+0.56)^1.6477)) -> 28.360157 | D5: =IF('WL & Q'!E5="","",'WL & Q'!E5) -> 0 | E5: 7 | F5: 8 | G5: 10
A6: ='WL & Q'!A6 -> 46232.083 | B6: =IF('WL & Q'!C6="","",'WL & Q'!C6) -> 0.47 | C6: =IF(B6="","",IF((B6+0.56)>4,13.194*(B6+0.56)^2+13.311*(B6+0.56)-0.8227,27.012*(B6+0.56)^1.6477)) -> 28.360157 | D6: =IF('WL & Q'!E6="","",'WL & Q'!E6) -> 0 | E6: 7 | F6: 8 | G6: 10
A7: ='WL & Q'!A7 -> 46232.125 | B7: =IF('WL & Q'!C7="","",'WL & Q'!C7) -> 0.48 | C7: =IF(B7="","",IF((B7+0.56)>4,13.194*(B7+0.56)^2+13.311*(B7+0.56)-0.8227,27.012*(B7+0.56)^1.6477)) -> 28.815262 | D7: =IF('WL & Q'!E7="","",'WL & Q'!E7) -> 0 | E7: 7 | F7: 8 | G7: 10
A8: ='WL & Q'!A8 -> 46232.167 | B8: =IF('WL & Q'!C8="","",'WL & Q'!C8) -> 0.49 | C8: =IF(B8="","",IF((B8+0.56)>4,13.194*(B8+0.56)^2+13.311*(B8+0.56)-0.8227,27.012*(B8+0.56)^1.6477)) -> 29.27321 | D8: =IF('WL & Q'!E8="","",'WL & Q'!E8) -> 0 | E8: 7 | F8: 8 | G8: 10
A9: ='WL & Q'!A9 -> 46232.208 | B9: =IF('WL & Q'!C9="","",'WL & Q'!C9) -> 0.51 | C9: =IF(B9="","",IF((B9+0.56)>4,13.194*(B9+0.56)^2+13.311*(B9+0.56)-0.8227,27.012*(B9+0.56)^1.6477)) -> 30.197597 | D9: =IF('WL & Q'!E9="","",'WL & Q'!E9) -> 0 | E9: 7 | F9: 8 | G9: 10
A10: ='WL & Q'!A10 -> 46232.25 | B10: =IF('WL & Q'!C10="","",'WL & Q'!C10) -> 0.55 | C10: =IF(B10="","",IF((B10+0.56)>4,13.194*(B10+0.56)^2+13.311*(B10+0.56)-0.8227,27.012*(B10+0.56)^1.6477)) -> 32.080078 | D10: =IF('WL & Q'!E10="","",'WL & Q'!E10) -> 3.1 | E10: 7 | F10: 8 | G10: 10
A11: ='WL & Q'!A11 -> 46232.292 | B11: =IF('WL & Q'!C11="","",'WL & Q'!C11) -> 0.64 | C11: =IF(B11="","",IF((B11+0.56)>4,13.194*(B11+0.56)^2+13.311*(B11+0.56)-0.8227,27.012*(B11+0.56)^1.6477)) -> 36.477384 | D11: =IF('WL & Q'!E11="","",'WL & Q'!E11) -> 1.5 | E11: 7 | F11: 8 | G11: 10
A12: ='WL & Q'!A12 -> 46232.333 | B12: =IF('WL & Q'!C12="","",'WL & Q'!C12) -> 0.66 | C12: =IF(B12="","",IF((B12+0.56)>4,13.194*(B12+0.56)^2+13.311*(B12+0.56)-0.8227,27.012*(B12+0.56)^1.6477)) -> 37.48451 | D12: =IF('WL & Q'!E12="","",'WL & Q'!E12) -> 0 | E12: 7 | F12: 8 | G12: 10
A13: ='WL & Q'!A13 -> 46232.375 | B13: =IF('WL & Q'!C13="","",'WL & Q'!C13) -> 0.68 | C13: =IF(B13="","",IF((B13+0.56)>4,13.194*(B13+0.56)^2+13.311*(B13+0.56)-0.8227,27.012*(B13+0.56)^1.6477)) -> 38.502387 | D13: =IF('WL & Q'!E13="","",'WL & Q'!E13) -> 0 | E13: 7 | F13: 8 | G13: 10
A14: ='WL & Q'!A14 -> 46232.417 | B14: =IF('WL & Q'!C14="","",'WL & Q'!C14) -> 0.69 | C14: =IF(B14="","",IF((B14+0.56)>4,13.194*(B14+0.56)^2+13.311*(B14+0.56)-0.8227,27.012*(B14+0.56)^1.6477)) -> 39.015338 | D14: =IF('WL & Q'!E14="","",'WL & Q'!E14) -> 0 | E14: 7 | F14: 8 | G14: 10
A15: ='WL & Q'!A15 -> 46232.458 | B15: =IF('WL & Q'!C15="","",'WL & Q'!C15) -> 0.7 | C15: =IF(B15="","",IF((B15+0.56)>4,13.194*(B15+0.56)^2+13.311*(B15+0.56)-0.8227,27.012*(B15+0.56)^1.6477)) -> 39.530953 | D15: =IF('WL & Q'!E15="","",'WL & Q'!E15) -> 0 | E15: 7 | F15: 8 | G15: 10
A16: ='WL & Q'!A16 -> 46232.5 | B16: =IF('WL & Q'!C16="","",'WL & Q'!C16) -> 0.7 | C16: =IF(B16="","",IF((B16+0.56)>4,13.194*(B16+0.56)^2+13.311*(B16+0.56)-0.8227,27.012*(B16+0.56)^1.6477)) -> 39.530953 | D16: =IF('WL & Q'!E16="","",'WL & Q'!E16) -> 0 | E16: 7 | F16: 8 | G16: 10
... A268: ='WL & Q'!A268 -> 46243 | B268: =IF('WL & Q'!C268="","",'WL & Q'!C268) | C268: =IF(B268="","",IF((B268+0.56)>4,13.194*(B268+0.56)^2+13.311*(B268+0.56)-0.8227,27.012*(B268+0.56)^1.6477)) | D268: =IF('WL & Q'!E268="","",'WL & Q'!E268) | E268: 7 | F268: 8 | G268: 10

Sheet Glencourse
A1: ='WL & Q'!A1 -> 2026 Kelani Flood
A2: Glencourse | I2: Range | J2: No 01 | K2: No 02 | L2: No 03 | M2: No 04
I3: 0 | J3: =Hanwella!J3 -> 46235.312 | K3: =Hanwella!K3 -> 46237.479 | L3: =Hanwella!L3 -> 46237.562 | M3: =Hanwella!M3 -> 46237.646
B4: WL (m) | C4: Q (m3s-1) | D4: RF | E4: Alert | F4: Minor | G4: Major | I4: 26 | J4: =Hanwella!J4 -> 46235.312 | K4: =Hanwella!K4 -> 46237.479 | L4: =Hanwella!L4 -> 46237.562 | M4: =Hanwella!M4 -> 46237.646
A5: ='WL & Q'!A5 -> 46232.042 | B5: =IF('WL & Q'!F5="","",'WL & Q'!F5) -> 8.85 | C5: =IF(B5="","",IF((B5-0.118)>14,9.8381*((B5-0.118)-7.5)^2+42.44*((B5-0.118)-7.5)-16.777,35.535*((B5-0.118)-7.5)^1.5414)) -> 49.014397 | D5: =IF('WL & Q'!H5="","",'WL & Q'!H5) -> 0 | E5: 15 | F5: 16.5 | G5: 19
A6: ='WL & Q'!A6 -> 46232.083 | B6: =IF('WL & Q'!F6="","",'WL & Q'!F6) -> 8.91 | C6: =IF(B6="","",IF((B6-0.118)>14,9.8381*((B6-0.118)-7.5)^2+42.44*((B6-0.118)-7.5)-16.777,35.535*((B6-0.118)-7.5)^1.5414)) -> 52.741971 | D6: =IF('WL & Q'!H6="","",'WL & Q'!H6) -> 1 | E6: 15 | F6: 16.5 | G6: 19
A7: ='WL & Q'!A7 -> 46232.125 | B7: =IF('WL & Q'!F7="","",'WL & Q'!F7) -> 9.05 | C7: =IF(B7="","",IF((B7-0.118)>14,9.8381*((B7-0.118)-7.5)^2+42.44*((B7-0.118)-7.5)-16.777,35.535*((B7-0.118)-7.5)^1.5414)) -> 61.805466 | D7: =IF('WL & Q'!H7="","",'WL & Q'!H7) -> 0 | E7: 15 | F7: 16.5 | G7: 19
A8: ='WL & Q'!A8 -> 46232.167 | B8: =IF('WL & Q'!F8="","",'WL & Q'!F8) -> 9.13 | C8: =IF(B8="","",IF((B8-0.118)>14,9.8381*((B8-0.118)-7.5)^2+42.44*((B8-0.118)-7.5)-16.777,35.535*((B8-0.118)-7.5)^1.5414)) -> 67.207455 | D8: =IF('WL & Q'!H8="","",'WL & Q'!H8) -> 0 | E8: 15 | F8: 16.5 | G8: 19
A9: ='WL & Q'!A9 -> 46232.208 | B9: =IF('WL & Q'!F9="","",'WL & Q'!F9) -> 9.1 | C9: =IF(B9="","",IF((B9-0.118)>14,9.8381*((B9-0.118)-7.5)^2+42.44*((B9-0.118)-7.5)-16.777,35.535*((B9-0.118)-7.5)^1.5414)) -> 65.163101 | D9: =IF('WL & Q'!H9="","",'WL & Q'!H9) -> 3.3 | E9: 15 | F9: 16.5 | G9: 19
A10: ='WL & Q'!A10 -> 46232.25 | B10: =IF('WL & Q'!F10="","",'WL & Q'!F10) -> 9.08 | C10: =IF(B10="","",IF((B10-0.118)>14,9.8381*((B10-0.118)-7.5)^2+42.44*((B10-0.118)-7.5)-16.777,35.535*((B10-0.118)-7.5)^1.5414)) -> 63.812565 | D10: =IF('WL & Q'!H10="","",'WL & Q'!H10) -> 0 | E10: 15 | F10: 16.5 | G10: 19
A11: ='WL & Q'!A11 -> 46232.292 | B11: =IF('WL & Q'!F11="","",'WL & Q'!F11) -> 9.06 | C11: =IF(B11="","",IF((B11-0.118)>14,9.8381*((B11-0.118)-7.5)^2+42.44*((B11-0.118)-7.5)-16.777,35.535*((B11-0.118)-7.5)^1.5414)) -> 62.471995 | D11: =IF('WL & Q'!H11="","",'WL & Q'!H11) -> 0.4 | E11: 15 | F11: 16.5 | G11: 19
A12: ='WL & Q'!A12 -> 46232.333 | B12: =IF('WL & Q'!F12="","",'WL & Q'!F12) -> 9.04 | C12: =IF(B12="","",IF((B12-0.118)>14,9.8381*((B12-0.118)-7.5)^2+42.44*((B12-0.118)-7.5)-16.777,35.535*((B12-0.118)-7.5)^1.5414)) -> 61.141453 | D12: =IF('WL & Q'!H12="","",'WL & Q'!H12) -> 0 | E12: 15 | F12: 16.5 | G12: 19
A13: ='WL & Q'!A13 -> 46232.375 | B13: =IF('WL & Q'!F13="","",'WL & Q'!F13) -> 9.03 | C13: =IF(B13="","",IF((B13-0.118)>14,9.8381*((B13-0.118)-7.5)^2+42.44*((B13-0.118)-7.5)-16.777,35.535*((B13-0.118)-7.5)^1.5414)) -> 60.479964 | D13: =IF('WL & Q'!H13="","",'WL & Q'!H13) -> 0 | E13: 15 | F13: 16.5 | G13: 19
A14: ='WL & Q'!A14 -> 46232.417 | B14: =IF('WL & Q'!F14="","",'WL & Q'!F14) -> 9.01 | C14: =IF(B14="","",IF((B14-0.118)>14,9.8381*((B14-0.118)-7.5)^2+42.44*((B14-0.118)-7.5)-16.777,35.535*((B14-0.118)-7.5)^1.5414)) -> 59.164587 | D14: =IF('WL & Q'!H14="","",'WL & Q'!H14) -> 1.2 | E14: 15 | F14: 16.5 | G14: 19
A15: ='WL & Q'!A15 -> 46232.458 | B15: =IF('WL & Q'!F15="","",'WL & Q'!F15) -> 9 | C15: =IF(B15="","",IF((B15-0.118)>14,9.8381*((B15-0.118)-7.5)^2+42.44*((B15-0.118)-7.5)-16.777,35.535*((B15-0.118)-7.5)^1.5414)) -> 58.510717 | D15: =IF('WL & Q'!H15="","",'WL & Q'!H15) -> 0 | E15: 15 | F15: 16.5 | G15: 19
A16: ='WL & Q'!A16 -> 46232.5 | B16: =IF('WL & Q'!F16="","",'WL & Q'!F16) -> 8.98 | C16: =IF(B16="","",IF((B16-0.118)>14,9.8381*((B16-0.118)-7.5)^2+42.44*((B16-0.118)-7.5)-16.777,35.535*((B16-0.118)-7.5)^1.5414)) -> 57.210654 | D16: =IF('WL & Q'!H16="","",'WL & Q'!H16) -> 0 | E16: 15 | F16: 16.5 | G16: 19
... A268: ='WL & Q'!A268 -> 46243 | B268: =IF('WL & Q'!F268="","",'WL & Q'!F268) | C268: =IF(B268="","",IF((B268-0.118)>14,9.8381*((B268-0.118)-7.5)^2+42.44*((B268-0.118)-7.5)-16.777,35.535*((B268-0.118)-7.5)^1.5414)) | D268: =IF('WL & Q'!H268="","",'WL & Q'!H268) | E268: 15 | F268: 16.5 | G268: 19

Sheet Kithulgala
A1: ='WL & Q'!A1 -> 2026 Kelani Flood
A2: Kithulgala | I2: Range | J2: No 01 | K2: No 02 | L2: No 03 | M2: No 04
I3: 0 | J3: =Hanwella!J3 -> 46235.312 | K3: =Hanwella!K3 -> 46237.479 | L3: =Hanwella!L3 -> 46237.562 | M3: =Hanwella!M3 -> 46237.646
B4: WL (m) | C4: Q (m3s-1) | D4: RF | E4: Alert | F4: Minor | G4: Major | I4: 8 | J4: =Hanwella!J4 -> 46235.312 | K4: =Hanwella!K4 -> 46237.479 | L4: =Hanwella!L4 -> 46237.562 | M4: =Hanwella!M4 -> 46237.646
A5: ='WL & Q'!A5 -> 46232.042 | B5: =IF('WL & Q'!I5="","",'WL & Q'!I5) -> 1.68 | C5: =IF(B5="","",IF(B5<=2.23,13.015*(B5-0.345)^3.274,114.59*(B5-0.345)^2-419*(B5-0.345)+487.77)) -> 33.517362 | D5: =IF('WL & Q'!J5="","",'WL & Q'!J5) -> 38.989318 | E5: 3 | F5: 4 | G5: 6
A6: ='WL & Q'!A6 -> 46232.083 | B6: =IF('WL & Q'!I6="","",'WL & Q'!I6) -> 1.66 | C6: =IF(B6="","",IF(B6<=2.23,13.015*(B6-0.345)^3.274,114.59*(B6-0.345)^2-419*(B6-0.345)+487.77)) -> 31.901205 | D6: =IF('WL & Q'!K6="","",'WL & Q'!K6) -> 0 | E6: 3 | F6: 4 | G6: 6
A7: ='WL & Q'!A7 -> 46232.125 | B7: =IF('WL & Q'!I7="","",'WL & Q'!I7) -> 1.66 | C7: =IF(B7="","",IF(B7<=2.23,13.015*(B7-0.345)^3.274,114.59*(B7-0.345)^2-419*(B7-0.345)+487.77)) -> 31.901205 | D7: =IF('WL & Q'!K7="","",'WL & Q'!K7) -> 0 | E7: 3 | F7: 4 | G7: 6
A8: ='WL & Q'!A8 -> 46232.167 | B8: =IF('WL & Q'!I8="","",'WL & Q'!I8) -> 1.59 | C8: =IF(B8="","",IF(B8<=2.23,13.015*(B8-0.345)^3.274,114.59*(B8-0.345)^2-419*(B8-0.345)+487.77)) -> 26.670345 | D8: =IF('WL & Q'!K8="","",'WL & Q'!K8) -> 0 | E8: 3 | F8: 4 | G8: 6
A9: ='WL & Q'!A9 -> 46232.208 | B9: =IF('WL & Q'!I9="","",'WL & Q'!I9) -> 1.59 | C9: =IF(B9="","",IF(B9<=2.23,13.015*(B9-0.345)^3.274,114.59*(B9-0.345)^2-419*(B9-0.345)+487.77)) -> 26.670345 | D9: =IF('WL & Q'!K9="","",'WL & Q'!K9) -> 9.8 | E9: 3 | F9: 4 | G9: 6
A10: ='WL & Q'!A10 -> 46232.25 | B10: =IF('WL & Q'!I10="","",'WL & Q'!I10) -> 1.61 | C10: =IF(B10="","",IF(B10<=2.23,13.015*(B10-0.345)^3.274,114.59*(B10-0.345)^2-419*(B10-0.345)+487.77)) -> 28.09885 | D10: =IF('WL & Q'!K10="","",'WL & Q'!K10) -> 7 | E10: 3 | F10: 4 | G10: 6
A11: ='WL & Q'!A11 -> 46232.292 | B11: =IF('WL & Q'!I11="","",'WL & Q'!I11) -> 1.68 | C11: =IF(B11="","",IF(B11<=2.23,13.015*(B11-0.345)^3.274,114.59*(B11-0.345)^2-419*(B11-0.345)+487.77)) -> 33.517362 | D11: =IF('WL & Q'!K11="","",'WL & Q'!K11) -> 1.2 | E11: 3 | F11: 4 | G11: 6
A12: ='WL & Q'!A12 -> 46232.333 | B12: =IF('WL & Q'!I12="","",'WL & Q'!I12) -> 1.55 | C12: =IF(B12="","",IF(B12<=2.23,13.015*(B12-0.345)^3.274,114.59*(B12-0.345)^2-419*(B12-0.345)+487.77)) -> 23.966012 | D12: =IF('WL & Q'!K12="","",'WL & Q'!K12) -> 0 | E12: 3 | F12: 4 | G12: 6
A13: ='WL & Q'!A13 -> 46232.375 | B13: =IF('WL & Q'!I13="","",'WL & Q'!I13) -> 1.55 | C13: =IF(B13="","",IF(B13<=2.23,13.015*(B13-0.345)^3.274,114.59*(B13-0.345)^2-419*(B13-0.345)+487.77)) -> 23.966012 | D13: =IF('WL & Q'!K13="","",'WL & Q'!K13) -> 0 | E13: 3 | F13: 4 | G13: 6
A14: ='WL & Q'!A14 -> 46232.417 | B14: =IF('WL & Q'!I14="","",'WL & Q'!I14) -> 1.33 | C14: =IF(B14="","",IF(B14<=2.23,13.015*(B14-0.345)^3.274,114.59*(B14-0.345)^2-419*(B14-0.345)+487.77)) -> 12.386665 | D14: =IF('WL & Q'!K14="","",'WL & Q'!K14) -> 0 | E14: 3 | F14: 4 | G14: 6
A15: ='WL & Q'!A15 -> 46232.458 | B15: =IF('WL & Q'!I15="","",'WL & Q'!I15) -> 1.43 | C15: =IF(B15="","",IF(B15<=2.23,13.015*(B15-0.345)^3.274,114.59*(B15-0.345)^2-419*(B15-0.345)+487.77)) -> 16.999695 | D15: =IF('WL & Q'!K15="","",'WL & Q'!K15) -> 1.8 | E15: 3 | F15: 4 | G15: 6
A16: ='WL & Q'!A16 -> 46232.5 | B16: =IF('WL & Q'!I16="","",'WL & Q'!I16) -> 1.45 | C16: =IF(B16="","",IF(B16<=2.23,13.015*(B16-0.345)^3.274,114.59*(B16-0.345)^2-419*(B16-0.345)+487.77)) -> 18.047301 | D16: =IF('WL & Q'!K16="","",'WL & Q'!K16) -> 4 | E16: 3 | F16: 4 | G16: 6
A17: ='WL & Q'!A17 -> 46232.542 | B17: =IF('WL & Q'!I17="","",'WL & Q'!I17) -> 1.63 | C17: =IF(B17="","",IF(B17<=2.23,13.015*(B17-0.345)^3.274,114.59*(B17-0.345)^2-419*(B17-0.345)+487.77)) -> 29.579649 | D17: =IF('WL & Q'!K17="","",'WL & Q'!K17) -> 0 | E17: 3 | F17: 4 | G17: 6
... A268: ='WL & Q'!A268 -> 46243 | B268: =IF('WL & Q'!I268="","",'WL & Q'!I268) | C268: =IF(B268="","",IF(B268<=2.23,13.015*(B268-0.345)^3.274,114.59*(B268-0.345)^2-419*(B268-0.345)+487.77)) | D268: =IF('WL & Q'!K268="","",'WL & Q'!K268) | E268: 3 | F268: 4 | G268: 6

Sheet Holombuwa
A1: ='WL & Q'!A1 -> 2026 Kelani Flood
A2: Holombuwa | I2: Range | J2: No 01 | K2: No 02 | L2: No 03 | M2: No 04
I3: 0 | J3: =Hanwella!J3 -> 46235.312 | K3: =Hanwella!K3 -> 46237.479 | L3: =Hanwella!L3 -> 46237.562 | M3: =Hanwella!M3 -> 46237.646
B4: WL (m) | C4: Q (m3s-1) | D4: RF | E4: Alert | F4: Minor | G4: Major | I4: 8 | J4: =Hanwella!J4 -> 46235.312 | K4: =Hanwella!K4 -> 46237.479 | L4: =Hanwella!L4 -> 46237.562 | M4: =Hanwella!M4 -> 46237.646
A5: ='WL & Q'!A5 -> 46232.042 | B5: =IF('WL & Q'!L5="","",'WL & Q'!L5) -> 0.3 | C5: =IF(B5="","",IF((B5)>2,8.9271*((B5)^2)+9.2434*(B5)-1.6791,14.51*(((B5)-0.1)^1.846))) -> 0.74365035 | D5: =IF('WL & Q'!N5="","",'WL & Q'!N5) -> 0 | E5: 3 | F5: 3.4 | G5: 5
A6: ='WL & Q'!A6 -> 46232.083 | B6: =IF('WL & Q'!L6="","",'WL & Q'!L6) -> 0.27 | C6: =IF(B6="","",IF((B6)>2,8.9271*((B6)^2)+9.2434*(B6)-1.6791,14.51*(((B6)-0.1)^1.846))) -> 0.55090425 | D6: =IF('WL & Q'!N6="","",'WL & Q'!N6) -> 2.8 | E6: 3 | F6: 3.4 | G6: 5
A7: ='WL & Q'!A7 -> 46232.125 | B7: =IF('WL & Q'!L7="","",'WL & Q'!L7) -> 0.24 | C7: =IF(B7="","",IF((B7)>2,8.9271*((B7)^2)+9.2434*(B7)-1.6791,14.51*(((B7)-0.1)^1.846))) -> 0.38496369 | D7: =IF('WL & Q'!N7="","",'WL & Q'!N7) -> 0 | E7: 3 | F7: 3.4 | G7: 5
A8: ='WL & Q'!A8 -> 46232.167 | B8: =IF('WL & Q'!L8="","",'WL & Q'!L8) -> 0.22 | C8: =IF(B8="","",IF((B8)>2,8.9271*((B8)^2)+9.2434*(B8)-1.6791,14.51*(((B8)-0.1)^1.846))) -> 0.28962496 | D8: =IF('WL & Q'!N8="","",'WL & Q'!N8) -> 0 | E8: 3 | F8: 3.4 | G8: 5
A9: ='WL & Q'!A9 -> 46232.208 | B9: =IF('WL & Q'!L9="","",'WL & Q'!L9) -> 0.22 | C9: =IF(B9="","",IF((B9)>2,8.9271*((B9)^2)+9.2434*(B9)-1.6791,14.51*(((B9)-0.1)^1.846))) -> 0.28962496 | D9: =IF('WL & Q'!N9="","",'WL & Q'!N9) -> 0 | E9: 3 | F9: 3.4 | G9: 5
A10: ='WL & Q'!A10 -> 46232.25 | B10: =IF('WL & Q'!L10="","",'WL & Q'!L10) -> 0.21 | C10: =IF(B10="","",IF((B10)>2,8.9271*((B10)^2)+9.2434*(B10)-1.6791,14.51*(((B10)-0.1)^1.846))) -> 0.2466484 | D10: =IF('WL & Q'!N10="","",'WL & Q'!N10) -> 0 | E10: 3 | F10: 3.4 | G10: 5
A11: ='WL & Q'!A11 -> 46232.292 | B11: =IF('WL & Q'!L11="","",'WL & Q'!L11) -> 0.21 | C11: =IF(B11="","",IF((B11)>2,8.9271*((B11)^2)+9.2434*(B11)-1.6791,14.51*(((B11)-0.1)^1.846))) -> 0.2466484 | D11: =IF('WL & Q'!N11="","",'WL & Q'!N11) -> 1.1 | E11: 3 | F11: 3.4 | G11: 5
A12: ='WL & Q'!A12 -> 46232.333 | B12: =IF('WL & Q'!L12="","",'WL & Q'!L12) -> 0.2 | C12: =IF(B12="","",IF((B12)>2,8.9271*((B12)^2)+9.2434*(B12)-1.6791,14.51*(((B12)-0.1)^1.846))) -> 0.20685566 | D12: =IF('WL & Q'!N12="","",'WL & Q'!N12) -> 0 | E12: 3 | F12: 3.4 | G12: 5
A13: ='WL & Q'!A13 -> 46232.375 | B13: =IF('WL & Q'!L13="","",'WL & Q'!L13) -> 0.2 | C13: =IF(B13="","",IF((B13)>2,8.9271*((B13)^2)+9.2434*(B13)-1.6791,14.51*(((B13)-0.1)^1.846))) -> 0.20685566 | D13: =IF('WL & Q'!N13="","",'WL & Q'!N13) -> 0 | E13: 3 | F13: 3.4 | G13: 5
A14: ='WL & Q'!A14 -> 46232.417 | B14: =IF('WL & Q'!L14="","",'WL & Q'!L14) -> 0.2 | C14: =IF(B14="","",IF((B14)>2,8.9271*((B14)^2)+9.2434*(B14)-1.6791,14.51*(((B14)-0.1)^1.846))) -> 0.20685566 | D14: =IF('WL & Q'!N14="","",'WL & Q'!N14) -> 0 | E14: 3 | F14: 3.4 | G14: 5
A15: ='WL & Q'!A15 -> 46232.458 | B15: =IF('WL & Q'!L15="","",'WL & Q'!L15) -> 0.2 | C15: =IF(B15="","",IF((B15)>2,8.9271*((B15)^2)+9.2434*(B15)-1.6791,14.51*(((B15)-0.1)^1.846))) -> 0.20685566 | D15: =IF('WL & Q'!N15="","",'WL & Q'!N15) -> 0 | E15: 3 | F15: 3.4 | G15: 5
A16: ='WL & Q'!A16 -> 46232.5 | B16: =IF('WL & Q'!L16="","",'WL & Q'!L16) -> 0.2 | C16: =IF(B16="","",IF((B16)>2,8.9271*((B16)^2)+9.2434*(B16)-1.6791,14.51*(((B16)-0.1)^1.846))) -> 0.20685566 | D16: =IF('WL & Q'!N16="","",'WL & Q'!N16) -> 0 | E16: 3 | F16: 3.4 | G16: 5
... A268: ='WL & Q'!A268 -> 46243 | B268: =IF('WL & Q'!L268="","",'WL & Q'!L268) | C268: =IF(B268="","",IF((B268)>2,8.9271*((B268)^2)+9.2434*(B268)-1.6791,14.51*(((B268)-0.1)^1.846))) | D268: =IF('WL & Q'!N268="","",'WL & Q'!N268) | E268: 3 | F268: 3.4 | G268: 5

Sheet Deraniyagala
A1: ='WL & Q'!A1 -> 2026 Kelani Flood
A2: Deraniyagala | I2: Range | J2: No 01 | K2: No 02 | L2: No 03 | M2: No 04
I3: 0 | J3: =Hanwella!J3 -> 46235.312 | K3: =Hanwella!K3 -> 46237.479 | L3: =Hanwella!L3 -> 46237.562 | M3: =Hanwella!M3 -> 46237.646
B4: WL (m) | C4: Q (m3s-1) | D4: RF | E4: Alert | F4: Minor | G4: Major | I4: 10 | J4: =Hanwella!J4 -> 46235.312 | K4: =Hanwella!K4 -> 46237.479 | L4: =Hanwella!L4 -> 46237.562 | M4: =Hanwella!M4 -> 46237.646
A5: ='WL & Q'!A5 -> 46232.042 | B5: =IF('WL & Q'!O5="","",'WL & Q'!O5) -> 0.57 | C5: =IF(B5="","",28.62*(B5)^1.3838) -> 13.147684 | D5: =IF('WL & Q'!Q5="","",'WL & Q'!Q5) -> 2.3 | E5: 4.8 | F5: 5.8 | G5: 6.4
A6: ='WL & Q'!A6 -> 46232.083 | B6: =IF('WL & Q'!O6="","",'WL & Q'!O6) -> 0.51 | C6: =IF(B6="","",28.62*(B6)^1.3838) -> 11.272111 | D6: =IF('WL & Q'!Q6="","",'WL & Q'!Q6) -> 0.5 | E6: 4.8 | F6: 5.8 | G6: 6.4
A7: ='WL & Q'!A7 -> 46232.125 | B7: =IF('WL & Q'!O7="","",'WL & Q'!O7) -> 0.45 | C7: =IF(B7="","",28.62*(B7)^1.3838) -> 9.4794929 | D7: =IF('WL & Q'!Q7="","",'WL & Q'!Q7) -> 0 | E7: 4.8 | F7: 5.8 | G7: 6.4
A8: ='WL & Q'!A8 -> 46232.167 | B8: =IF('WL & Q'!O8="","",'WL & Q'!O8) -> 0.43 | C8: =IF(B8="","",28.62*(B8)^1.3838) -> 8.9015017 | D8: =IF('WL & Q'!Q8="","",'WL & Q'!Q8) -> 0 | E8: 4.8 | F8: 5.8 | G8: 6.4
A9: ='WL & Q'!A9 -> 46232.208 | B9: =IF('WL & Q'!O9="","",'WL & Q'!O9) -> 0.43 | C9: =IF(B9="","",28.62*(B9)^1.3838) -> 8.9015017 | D9: =IF('WL & Q'!Q9="","",'WL & Q'!Q9) -> 8.2 | E9: 4.8 | F9: 5.8 | G9: 6.4
A10: ='WL & Q'!A10 -> 46232.25 | B10: =IF('WL & Q'!O10="","",'WL & Q'!O10) -> 0.45 | C10: =IF(B10="","",28.62*(B10)^1.3838) -> 9.4794929 | D10: =IF('WL & Q'!Q10="","",'WL & Q'!Q10) -> 0.9 | E10: 4.8 | F10: 5.8 | G10: 6.4
A11: ='WL & Q'!A11 -> 46232.292 | B11: =IF('WL & Q'!O11="","",'WL & Q'!O11) -> 0.51 | C11: =IF(B11="","",28.62*(B11)^1.3838) -> 11.272111 | D11: =IF('WL & Q'!Q11="","",'WL & Q'!Q11) -> 0.6 | E11: 4.8 | F11: 5.8 | G11: 6.4
A12: ='WL & Q'!A12 -> 46232.333 | B12: =IF('WL & Q'!O12="","",'WL & Q'!O12) -> 0.54 | C12: =IF(B12="","",28.62*(B12)^1.3838) -> 12.199896 | D12: =IF('WL & Q'!Q12="","",'WL & Q'!Q12) -> 0 | E12: 4.8 | F12: 5.8 | G12: 6.4
A13: ='WL & Q'!A13 -> 46232.375 | B13: =IF('WL & Q'!O13="","",'WL & Q'!O13) -> 0.63 | C13: =IF(B13="","",28.62*(B13)^1.3838) -> 15.1007 | D13: =IF('WL & Q'!Q13="","",'WL & Q'!Q13) -> 0 | E13: 4.8 | F13: 5.8 | G13: 6.4
A14: ='WL & Q'!A14 -> 46232.417 | B14: =IF('WL & Q'!O14="","",'WL & Q'!O14) -> 0.63 | C14: =IF(B14="","",28.62*(B14)^1.3838) -> 15.1007 | D14: =IF('WL & Q'!Q14="","",'WL & Q'!Q14) -> 0 | E14: 4.8 | F14: 5.8 | G14: 6.4
A15: ='WL & Q'!A15 -> 46232.458 | B15: =IF('WL & Q'!O15="","",'WL & Q'!O15) -> 0.48 | C15: =IF(B15="","",28.62*(B15)^1.3838) -> 10.365046 | D15: =IF('WL & Q'!Q15="","",'WL & Q'!Q15) -> 0 | E15: 4.8 | F15: 5.8 | G15: 6.4
A16: ='WL & Q'!A16 -> 46232.5 | B16: =IF('WL & Q'!O16="","",'WL & Q'!O16) -> 0.44 | C16: =IF(B16="","",28.62*(B16)^1.3838) -> 9.1892368 | D16: =IF('WL & Q'!Q16="","",'WL & Q'!Q16) -> 0.4 | E16: 4.8 | F16: 5.8 | G16: 6.4
... A268: ='WL & Q'!A268 -> 46243 | B268: =IF('WL & Q'!O268="","",'WL & Q'!O268) | C268: =IF(B268="","",28.62*(B268)^1.3838) | D268: =IF('WL & Q'!Q268="","",'WL & Q'!Q268) | E268: 4.8 | F268: 5.8 | G268: 6.4

Sheet Norwood
A1: ='WL & Q'!A1 -> 2026 Kelani Flood
A2: Norwood | I2: Range | J2: No 01 | K2: No 02 | L2: No 03 | M2: No 04
I3: 0 | J3: =Hanwella!J3 -> 46235.312 | K3: =Hanwella!K3 -> 46237.479 | L3: =Hanwella!L3 -> 46237.562 | M3: =Hanwella!M3 -> 46237.646
B4: WL (m) | C4: Q (m3s-1) | D4: RF | E4: Alert | F4: Minor | G4: Major | I4: 5 | J4: =Hanwella!J4 -> 46235.312 | K4: =Hanwella!K4 -> 46237.479 | L4: =Hanwella!L4 -> 46237.562 | M4: =Hanwella!M4 -> 46237.646
A5: ='WL & Q'!A5 -> 46232.042 | B5: =IF('WL & Q'!R5="","",'WL & Q'!R5) -> 0.42 | C5: =IF(B5="","",IF(B5>2.5,19.135*(B5+0.5)^2-29.477*(B5+0.5)+32.54,3.0494*((B5+0.5)^2.8875))) -> 2.3969101 | D5: =IF('WL & Q'!T5="","",'WL & Q'!T5) -> 1.5 | E5: 1.5 | F5: 3 | G5: 4.5
A6: ='WL & Q'!A6 -> 46232.083 | B6: =IF('WL & Q'!R6="","",'WL & Q'!R6) -> 0.42 | C6: =IF(B6="","",IF(B6>2.5,19.135*(B6+0.5)^2-29.477*(B6+0.5)+32.54,3.0494*((B6+0.5)^2.8875))) -> 2.3969101 | D6: =IF('WL & Q'!T6="","",'WL & Q'!T6) -> 0 | E6: 1.5 | F6: 3 | G6: 4.5
A7: ='WL & Q'!A7 -> 46232.125 | B7: =IF('WL & Q'!R7="","",'WL & Q'!R7) -> 0.41 | C7: =IF(B7="","",IF(B7>2.5,19.135*(B7+0.5)^2-29.477*(B7+0.5)+32.54,3.0494*((B7+0.5)^2.8875))) -> 2.3224502 | D7: =IF('WL & Q'!T7="","",'WL & Q'!T7) -> 1 | E7: 1.5 | F7: 3 | G7: 4.5
A8: ='WL & Q'!A8 -> 46232.167 | B8: =IF('WL & Q'!R8="","",'WL & Q'!R8) -> 0.42 | C8: =IF(B8="","",IF(B8>2.5,19.135*(B8+0.5)^2-29.477*(B8+0.5)+32.54,3.0494*((B8+0.5)^2.8875))) -> 2.3969101 | D8: =IF('WL & Q'!T8="","",'WL & Q'!T8) -> 0 | E8: 1.5 | F8: 3 | G8: 4.5
A9: ='WL & Q'!A9 -> 46232.208 | B9: =IF('WL & Q'!R9="","",'WL & Q'!R9) -> 0.44 | C9: =IF(B9="","",IF(B9>2.5,19.135*(B9+0.5)^2-29.477*(B9+0.5)+32.54,3.0494*((B9+0.5)^2.8875))) -> 2.550475 | D9: =IF('WL & Q'!T9="","",'WL & Q'!T9) -> 0 | E9: 1.5 | F9: 3 | G9: 4.5
A10: ='WL & Q'!A10 -> 46232.25 | B10: =IF('WL & Q'!R10="","",'WL & Q'!R10) -> 0.45 | C10: =IF(B10="","",IF(B10>2.5,19.135*(B10+0.5)^2-29.477*(B10+0.5)+32.54,3.0494*((B10+0.5)^2.8875))) -> 2.6296098 | D10: =IF('WL & Q'!T10="","",'WL & Q'!T10) -> 0 | E10: 1.5 | F10: 3 | G10: 4.5
A11: ='WL & Q'!A11 -> 46232.292 | B11: =IF('WL & Q'!R11="","",'WL & Q'!R11) -> 0.45 | C11: =IF(B11="","",IF(B11>2.5,19.135*(B11+0.5)^2-29.477*(B11+0.5)+32.54,3.0494*((B11+0.5)^2.8875))) -> 2.6296098 | D11: =IF('WL & Q'!T11="","",'WL & Q'!T11) -> 1.2 | E11: 1.5 | F11: 3 | G11: 4.5
A12: ='WL & Q'!A12 -> 46232.333 | B12: =IF('WL & Q'!R12="","",'WL & Q'!R12) -> 0.46 | C12: =IF(B12="","",IF(B12>2.5,19.135*(B12+0.5)^2-29.477*(B12+0.5)+32.54,3.0494*((B12+0.5)^2.8875))) -> 2.7103326 | D12: =IF('WL & Q'!T12="","",'WL & Q'!T12) -> 0 | E12: 1.5 | F12: 3 | G12: 4.5
A13: ='WL & Q'!A13 -> 46232.375 | B13: =IF('WL & Q'!R13="","",'WL & Q'!R13) -> 0.46 | C13: =IF(B13="","",IF(B13>2.5,19.135*(B13+0.5)^2-29.477*(B13+0.5)+32.54,3.0494*((B13+0.5)^2.8875))) -> 2.7103326 | D13: =IF('WL & Q'!T13="","",'WL & Q'!T13) -> 0 | E13: 1.5 | F13: 3 | G13: 4.5
A14: ='WL & Q'!A14 -> 46232.417 | B14: =IF('WL & Q'!R14="","",'WL & Q'!R14) -> 0.47 | C14: =IF(B14="","",IF(B14>2.5,19.135*(B14+0.5)^2-29.477*(B14+0.5)+32.54,3.0494*((B14+0.5)^2.8875))) -> 2.7926582 | D14: =IF('WL & Q'!T14="","",'WL & Q'!T14) -> 0 | E14: 1.5 | F14: 3 | G14: 4.5
A15: ='WL & Q'!A15 -> 46232.458 | B15: =IF('WL & Q'!R15="","",'WL & Q'!R15) -> 0.48 | C15: =IF(B15="","",IF(B15>2.5,19.135*(B15+0.5)^2-29.477*(B15+0.5)+32.54,3.0494*((B15+0.5)^2.8875))) -> 2.8766014 | D15: =IF('WL & Q'!T15="","",'WL & Q'!T15) -> 1.6 | E15: 1.5 | F15: 3 | G15: 4.5
A16: ='WL & Q'!A16 -> 46232.5 | B16: =IF('WL & Q'!R16="","",'WL & Q'!R16) -> 0.48 | C16: =IF(B16="","",IF(B16>2.5,19.135*(B16+0.5)^2-29.477*(B16+0.5)+32.54,3.0494*((B16+0.5)^2.8875))) -> 2.8766014 | D16: =IF('WL & Q'!T16="","",'WL & Q'!T16) -> 0 | E16: 1.5 | F16: 3 | G16: 4.5
... A268: ='WL & Q'!A268 -> 46243 | B268: =IF('WL & Q'!R268="","",'WL & Q'!R268) | C268: =IF(B268="","",IF(B268>2.5,19.135*(B268+0.5)^2-29.477*(B268+0.5)+32.54,3.0494*((B268+0.5)^2.8875))) | D268: =IF('WL & Q'!T268="","",'WL & Q'!T268) | E268: 1.5 | F268: 3 | G268: 4.5
